  0%|                                        | 0/2501 [00:00<?, ?it/s]pydev debugger: warning: trying to add breakpoint to file that does not exist: /home/psh/.cache/JetBrains/PyCharm2021.2/remote_sources/246745051/-1924635245/monai/inferers/utils.py (will have no effect)
pydev debugger: warning: trying to add breakpoint to file that does not exist: /home/psh/.cache/JetBrains/PyCharm2021.2/remote_sources/246745051/-1924635245/monai/inferers/utils.py (will have no effect)
pydev debugger: warning: trying to add breakpoint to file that does not exist: /home/psh/.cache/JetBrains/PyCharm2021.2/remote_sources/246745051/-1924635245/monai/inferers/utils.py (will have no effect)
pydev debugger: warning: trying to add breakpoint to file that does not exist: /home/psh/.cache/JetBrains/PyCharm2021.2/remote_sources/246745051/-1924635245/monai/inferers/utils.py (will have no effect)
pydev debugger: warning: trying to add breakpoint to file that does not exist: /home/psh/.cache/JetBrains/PyCharm2021.2/remote_sources/246745051/-1924635245/monai/inferers/utils.py (will have no effect)
pydev debugger: warning: trying to add breakpoint to file that does not exist: /home/psh/.cache/JetBrains/PyCharm2021.2/remote_sources/246745051/-1924635245/monai/inferers/utils.py (will have no effect)
pydev debugger: warning: trying to add breakpoint to file that does not exist: /home/psh/.cache/JetBrains/PyCharm2021.2/remote_sources/246745051/-1924635245/monai/inferers/utils.py (will have no effect)
pydev debugger: warning: trying to add breakpoint to file that does not exist: /home/psh/.cache/JetBrains/PyCharm2021.2/remote_sources/246745051/-1924635245/monai/inferers/utils.py (will have no effect)
pydev debugger: warning: trying to add breakpoint to file that does not exist: /home/psh/.cache/JetBrains/PyCharm2021.2/remote_sources/246745051/-1924635245/monai/inferers/utils.py (will have no effect)
pydev debugger: warning: trying to add breakpoint to file that does not exist: /home/psh/.cache/JetBrains/PyCharm2021.2/remote_sources/246745051/-1924635245/monai/inferers/utils.py (will have no effect)
pydev debugger: warning: trying to add breakpoint to file that does not exist: /home/psh/.cache/JetBrains/PyCharm2021.2/remote_sources/246745051/-1924635245/monai/inferers/utils.py (will have no effect)
pydev debugger: warning: trying to add breakpoint to file that does not exist: /home/psh/.cache/JetBrains/PyCharm2021.2/remote_sources/246745051/-1924635245/monai/inferers/utils.py (will have no effect)
pydev debugger: warning: trying to add breakpoint to file that does not exist: /home/psh/.cache/JetBrains/PyCharm2021.2/remote_sources/246745051/-1924635245/monai/inferers/utils.py (will have no effect)
pydev debugger: warning: trying to add breakpoint to file that does not exist: /home/psh/.cache/JetBrains/PyCharm2021.2/remote_sources/246745051/-1924635245/monai/inferers/utils.py (will have no effect)
Namespace(T=1, base_lr=0.01, batch_size=4, consistency=0.1, consistency_rampup=40.0, consistency_type='mse', deterministic=1, ema_decay=0.99, exp='UAMT', gpu='6', labeled_bs=2, labeled_num=25, max_iterations=30000, model='test', num_classes=2, patch_size=[96, 96, 96], root_path='/data/sohui/BraTS/data/BraTs2019', seed=1337, total_labeled_num=250)
total 250 samples
12 iterations per epoch
  0%|                                        | 0/2501 [00:02<?, ?it/s]
Traceback (most recent call last):
  File "/home/sohui/.pycharm_helpers/pydev/pydevd.py", line 1483, in _exec
    pydev_imports.execfile(file, globals, locals)  # execute the script
  File "/home/sohui/.pycharm_helpers/pydev/_pydev_imps/_pydev_execfile.py", line 18, in execfile
    exec(compile(contents+"\n", file, 'exec'), glob, loc)
  File "/home/sohui/code/SSL_brats/code/Brats2_MT_UA2avg_2task_SDM_2Dec_Uncertainty_ConsisModi.py", line 330, in <module>
    train(args, snapshot_path)
  File "/home/sohui/code/SSL_brats/code/Brats2_MT_UA2avg_2task_SDM_2Dec_Uncertainty_ConsisModi.py", line 168, in train
    outputs_2class, outputs_1class_tanh = model(volume_batch)  ## model = student
  File "/home/sohui/miniconda3/envs/test/lib/python3.8/site-packages/torch/nn/modules/module.py", line 889, in _call_impl
    result = self.forward(*input, **kwargs)
  File "/home/sohui/code/SSL_brats/code/networks/vnet_2task_SDM_2Dec.py", line 328, in forward
    out_SDM = self.decoder_SDM(features)
  File "/home/sohui/miniconda3/envs/test/lib/python3.8/site-packages/torch/nn/modules/module.py", line 889, in _call_impl
    result = self.forward(*input, **kwargs)
  File "/home/sohui/code/SSL_brats/code/networks/vnet_2task_SDM_2Dec.py", line 286, in forward
    x8_up = x8_up + x1
RuntimeError: CUDA out of memory. Tried to allocate 216.00 MiB (GPU 0; 11.91 GiB total capacity; 3.77 GiB already allocated; 9.94 MiB free; 3.79 GiB reserved in total by PyTorch)