2023-04-19 13:28:42,673 INFO    MainThread:22902 [internal.py:wandb_internal():87] W&B internal server running at pid: 22902, started at: 2023-04-19 13:28:42.672802
2023-04-19 13:28:42,675 INFO    WriterThread:22902 [datastore.py:open_for_write():77] open: /home/sohui/code/SSL_brats/code/wandb/run-20230419_132841-1ixhq6wq/run-1ixhq6wq.wandb
2023-04-19 13:28:42,676 DEBUG   HandlerThread:22902 [handler.py:handle_request():130] handle_request: check_version
2023-04-19 13:28:42,678 DEBUG   SenderThread:22902 [sender.py:send():234] send: header
2023-04-19 13:28:42,678 DEBUG   SenderThread:22902 [sender.py:send_request():248] send_request: check_version
2023-04-19 13:28:42,735 DEBUG   SenderThread:22902 [sender.py:send():234] send: run
2023-04-19 13:28:54,101 ERROR   SenderThread:22902 [internal_api.py:execute():144] 500 response executing GraphQL.
2023-04-19 13:28:54,101 ERROR   SenderThread:22902 [internal_api.py:execute():145] {"errors":[{"message":"An internal error occurred. Please contact support.","path":["upsertBucket"]}],"data":{"upsertBucket":null}}
2023-04-19 13:29:06,394 ERROR   SenderThread:22902 [retry.py:__call__():126] Retry attempt failed:
Traceback (most recent call last):
  File "/home/sohui/miniconda3/envs/test/lib/python3.8/site-packages/urllib3/connectionpool.py", line 445, in _make_request
    six.raise_from(e, None)
  File "<string>", line 3, in raise_from
  File "/home/sohui/miniconda3/envs/test/lib/python3.8/site-packages/urllib3/connectionpool.py", line 440, in _make_request
    httplib_response = conn.getresponse()
  File "/home/sohui/miniconda3/envs/test/lib/python3.8/http/client.py", line 1344, in getresponse
    response.begin()
  File "/home/sohui/miniconda3/envs/test/lib/python3.8/http/client.py", line 307, in begin
    version, status, reason = self._read_status()
  File "/home/sohui/miniconda3/envs/test/lib/python3.8/http/client.py", line 268, in _read_status
    line = str(self.fp.readline(_MAXLINE + 1), "iso-8859-1")
  File "/home/sohui/miniconda3/envs/test/lib/python3.8/socket.py", line 669, in readinto
    return self._sock.recv_into(b)
  File "/home/sohui/miniconda3/envs/test/lib/python3.8/ssl.py", line 1241, in recv_into
    return self.read(nbytes, buffer)
  File "/home/sohui/miniconda3/envs/test/lib/python3.8/ssl.py", line 1099, in read
    return self._sslobj.read(len, buffer)
socket.timeout: The read operation timed out

During handling of the above exception, another exception occurred:

Traceback (most recent call last):
  File "/home/sohui/miniconda3/envs/test/lib/python3.8/site-packages/requests/adapters.py", line 439, in send
    resp = conn.urlopen(
  File "/home/sohui/miniconda3/envs/test/lib/python3.8/site-packages/urllib3/connectionpool.py", line 755, in urlopen
    retries = retries.increment(
  File "/home/sohui/miniconda3/envs/test/lib/python3.8/site-packages/urllib3/util/retry.py", line 532, in increment
    raise six.reraise(type(error), error, _stacktrace)
  File "/home/sohui/miniconda3/envs/test/lib/python3.8/site-packages/urllib3/packages/six.py", line 770, in reraise
    raise value
  File "/home/sohui/miniconda3/envs/test/lib/python3.8/site-packages/urllib3/connectionpool.py", line 699, in urlopen
    httplib_response = self._make_request(
  File "/home/sohui/miniconda3/envs/test/lib/python3.8/site-packages/urllib3/connectionpool.py", line 447, in _make_request
    self._raise_timeout(err=e, url=url, timeout_value=read_timeout)
  File "/home/sohui/miniconda3/envs/test/lib/python3.8/site-packages/urllib3/connectionpool.py", line 336, in _raise_timeout
    raise ReadTimeoutError(
urllib3.exceptions.ReadTimeoutError: HTTPSConnectionPool(host='api.wandb.ai', port=443): Read timed out. (read timeout=10)

During handling of the above exception, another exception occurred:

Traceback (most recent call last):
  File "/home/sohui/miniconda3/envs/test/lib/python3.8/site-packages/wandb/sdk/lib/retry.py", line 102, in __call__
    result = self._call_fn(*args, **kwargs)
  File "/home/sohui/miniconda3/envs/test/lib/python3.8/site-packages/wandb/sdk/internal/internal_api.py", line 141, in execute
    return self.client.execute(*args, **kwargs)
  File "/home/sohui/miniconda3/envs/test/lib/python3.8/site-packages/wandb/vendor/gql-0.2.0/gql/client.py", line 52, in execute
    result = self._get_result(document, *args, **kwargs)
  File "/home/sohui/miniconda3/envs/test/lib/python3.8/site-packages/wandb/vendor/gql-0.2.0/gql/client.py", line 60, in _get_result
    return self.transport.execute(document, *args, **kwargs)
  File "/home/sohui/miniconda3/envs/test/lib/python3.8/site-packages/wandb/vendor/gql-0.2.0/gql/transport/requests.py", line 38, in execute
    request = requests.post(self.url, **post_args)
  File "/home/sohui/miniconda3/envs/test/lib/python3.8/site-packages/requests/api.py", line 117, in post
    return request('post', url, data=data, json=json, **kwargs)
  File "/home/sohui/miniconda3/envs/test/lib/python3.8/site-packages/requests/api.py", line 61, in request
    return session.request(method=method, url=url, **kwargs)
  File "/home/sohui/miniconda3/envs/test/lib/python3.8/site-packages/requests/sessions.py", line 542, in request
    resp = self.send(prep, **send_kwargs)
  File "/home/sohui/miniconda3/envs/test/lib/python3.8/site-packages/requests/sessions.py", line 655, in send
    r = adapter.send(request, **kwargs)
  File "/home/sohui/miniconda3/envs/test/lib/python3.8/site-packages/requests/adapters.py", line 529, in send
    raise ReadTimeout(e, request=request)
requests.exceptions.ReadTimeout: HTTPSConnectionPool(host='api.wandb.ai', port=443): Read timed out. (read timeout=10)
2023-04-19 13:29:12,735 DEBUG   HandlerThread:22902 [handler.py:handle_request():130] handle_request: shutdown
2023-04-19 13:29:12,735 INFO    HandlerThread:22902 [handler.py:finish():731] shutting down handler
2023-04-19 13:29:12,740 INFO    WriterThread:22902 [datastore.py:close():281] close: /home/sohui/code/SSL_brats/code/wandb/run-20230419_132841-1ixhq6wq/run-1ixhq6wq.wandb
2023-04-19 13:29:28,875 INFO    SenderThread:22902 [dir_watcher.py:__init__():169] watching files in: /home/sohui/code/SSL_brats/code/wandb/run-20230419_132841-1ixhq6wq/files
2023-04-19 13:29:28,875 INFO    SenderThread:22902 [sender.py:_start_run_threads():804] run started: 1ixhq6wq with start time 1681878521
2023-04-19 13:29:28,875 INFO    SenderThread:22902 [sender.py:finish():1070] shutting down sender
2023-04-19 13:29:28,875 INFO    SenderThread:22902 [dir_watcher.py:finish():283] shutting down directory watcher
2023-04-19 13:29:29,876 INFO    SenderThread:22902 [dir_watcher.py:finish():313] scan: /home/sohui/code/SSL_brats/code/wandb/run-20230419_132841-1ixhq6wq/files
2023-04-19 13:29:29,876 INFO    SenderThread:22902 [dir_watcher.py:finish():327] scan save: /home/sohui/code/SSL_brats/code/wandb/run-20230419_132841-1ixhq6wq/files/config.yaml config.yaml
2023-04-19 13:29:29,876 INFO    SenderThread:22902 [file_pusher.py:finish():177] shutting down file pusher
2023-04-19 13:29:29,876 INFO    SenderThread:22902 [file_pusher.py:join():182] waiting for file pusher
2023-04-19 13:29:30,676 INFO    Thread-10 :22902 [upload_job.py:push():137] Uploaded file /home/sohui/code/SSL_brats/code/wandb/run-20230419_132841-1ixhq6wq/files/config.yaml
2023-04-19 13:29:31,162 INFO    MainThread:22902 [internal.py:handle_exit():77] Internal process exited
