
Namespace(D_lr=0.0001, base_lr=0.01, batch_size=4, beta=0.3, consistency=1.0, consistency_rampup=40.0, consistency_type='kl', consistency_weight=0.1, deterministic=1, ema_decay=0.99, exp='DTC', fold=1, gamma=0.5, gpu='4', labeled_bs=2, labelnum=25, max_iterations=30000, model='test', root_path='/data/sohui/BraTS/data/BraTs2019', seed=1337, total_data_num=250, with_cons='without_cons')
  0%|                                        | 0/2501 [00:00<?, ?it/s]pydev debugger: warning: trying to add breakpoint to file that does not exist: /home/psh/.cache/JetBrains/PyCharm2021.2/remote_sources/246745051/-1924635245/monai/inferers/utils.py (will have no effect)
pydev debugger: warning: trying to add breakpoint to file that does not exist: /home/psh/.cache/JetBrains/PyCharm2021.2/remote_sources/246745051/-1924635245/monai/inferers/utils.py (will have no effect)
total 268 samples
12 itertations per epoch
pydev debugger: warning: trying to add breakpoint to file that does not exist: /home/psh/.cache/JetBrains/PyCharm2021.2/remote_sources/246745051/-1924635245/monai/inferers/utils.py (will have no effect)
pydev debugger: warning: trying to add breakpoint to file that does not exist: /home/psh/.cache/JetBrains/PyCharm2021.2/remote_sources/246745051/-1924635245/monai/inferers/utils.py (will have no effect)
pydev debugger: warning: trying to add breakpoint to file that does not exist: /home/psh/.cache/JetBrains/PyCharm2021.2/remote_sources/246745051/-1924635245/monai/inferers/utils.py (will have no effect)
pydev debugger: warning: trying to add breakpoint to file that does not exist: /home/psh/.cache/JetBrains/PyCharm2021.2/remote_sources/246745051/-1924635245/monai/inferers/utils.py (will have no effect)
pydev debugger: warning: trying to add breakpoint to file that does not exist: /home/psh/.cache/JetBrains/PyCharm2021.2/remote_sources/246745051/-1924635245/monai/inferers/utils.py (will have no effect)
pydev debugger: warning: trying to add breakpoint to file that does not exist: /home/psh/.cache/JetBrains/PyCharm2021.2/remote_sources/246745051/-1924635245/monai/inferers/utils.py (will have no effect)
pydev debugger: warning: trying to add breakpoint to file that does not exist: /home/psh/.cache/JetBrains/PyCharm2021.2/remote_sources/246745051/-1924635245/monai/inferers/utils.py (will have no effect)
pydev debugger: warning: trying to add breakpoint to file that does not exist: /home/psh/.cache/JetBrains/PyCharm2021.2/remote_sources/246745051/-1924635245/monai/inferers/utils.py (will have no effect)
pydev debugger: warning: trying to add breakpoint to file that does not exist: /home/psh/.cache/JetBrains/PyCharm2021.2/remote_sources/246745051/-1924635245/monai/inferers/utils.py (will have no effect)
pydev debugger: warning: trying to add breakpoint to file that does not exist: /home/psh/.cache/JetBrains/PyCharm2021.2/remote_sources/246745051/-1924635245/monai/inferers/utils.py (will have no effect)
pydev debugger: warning: trying to add breakpoint to file that does not exist: /home/psh/.cache/JetBrains/PyCharm2021.2/remote_sources/246745051/-1924635245/monai/inferers/utils.py (will have no effect)
pydev debugger: warning: trying to add breakpoint to file that does not exist: /home/psh/.cache/JetBrains/PyCharm2021.2/remote_sources/246745051/-1924635245/monai/inferers/utils.py (will have no effect)
iteration 1 : loss : 0.895628, loss_consis: 0.249653, loss_haus: 0.225009, loss_seg: 0.724269, loss_dice: 0.826443
iteration 1 : loss : 0.895628
Validation begin
  0%|                                                    | 0/67 [00:00<?, ?it/s]
  0%|                                        | 0/2501 [01:02<?, ?it/s]<?, ?it/s]
Traceback (most recent call last):
  File "/home/sohui/miniconda3/envs/test/lib/python3.8/site-packages/h5py/_hl/files.py", line 533, in __init__
    fid = make_fid(name, mode, userblock_size, fapl, fcpl, swmr=swmr)
  File "/home/sohui/miniconda3/envs/test/lib/python3.8/site-packages/h5py/_hl/files.py", line 226, in make_fid
    fid = h5f.open(name, flags, fapl=fapl)
  File "h5py/_objects.pyx", line 54, in h5py._objects.with_phil.wrapper
  File "h5py/_objects.pyx", line 55, in h5py._objects.with_phil.wrapper
  File "h5py/h5f.pyx", line 106, in h5py.h5f.open
FileNotFoundError: [Errno 2] Unable to open file (unable to open file: name = '/data/sohui/BraTS/data/BraTs2019/fold1/BraTS19_2013_0_1.h5', errno = 2, error message = 'No such file or directory', flags = 0, o_flags = 0)