2023-04-19 13:28:21,180 INFO    MainThread:22554 [wandb_setup.py:_flush():71] setting env: {}
2023-04-19 13:28:21,180 INFO    MainThread:22554 [wandb_setup.py:_flush():71] setting login settings: {}
2023-04-19 13:28:21,180 INFO    MainThread:22554 [wandb_init.py:_log_setup():371] Logging user logs to /home/sohui/code/SSL_brats/code/wandb/run-20230419_132821-335vdtgb/logs/debug.log
2023-04-19 13:28:21,180 INFO    MainThread:22554 [wandb_init.py:_log_setup():372] Logging internal logs to /home/sohui/code/SSL_brats/code/wandb/run-20230419_132821-335vdtgb/logs/debug-internal.log
2023-04-19 13:28:21,181 INFO    MainThread:22554 [wandb_init.py:init():404] calling init triggers
2023-04-19 13:28:21,181 INFO    MainThread:22554 [wandb_init.py:init():409] wandb.init called with sweep_config: {}
config: {}
2023-04-19 13:28:21,181 INFO    MainThread:22554 [wandb_init.py:init():460] starting backend
2023-04-19 13:28:21,181 INFO    MainThread:22554 [backend.py:_multiprocessing_setup():99] multiprocessing start_methods=fork,spawn,forkserver, using: spawn
2023-04-19 13:28:21,199 INFO    MainThread:22554 [backend.py:ensure_launched():216] starting backend process...
2023-04-19 13:28:21,212 INFO    MainThread:22554 [backend.py:ensure_launched():221] started backend process with pid: 22710
2023-04-19 13:28:21,213 INFO    MainThread:22554 [wandb_init.py:init():469] backend started and connected
2023-04-19 13:28:21,219 INFO    MainThread:22554 [wandb_init.py:init():533] updated telemetry
2023-04-19 13:28:21,220 INFO    MainThread:22554 [wandb_init.py:init():563] communicating current version
2023-04-19 13:28:22,370 INFO    MainThread:22554 [wandb_init.py:init():568] got version response upgrade_message: "wandb version 0.14.2 is available!  To upgrade, please run:\n $ pip install wandb --upgrade"

2023-04-19 13:28:22,370 INFO    MainThread:22554 [wandb_init.py:init():578] communicating run to backend with 30 second timeout
2023-04-19 13:28:24,998 ERROR   Thread-1  :22554 [internal_api.py:execute():144] 500 response executing GraphQL.
2023-04-19 13:28:24,999 ERROR   Thread-1  :22554 [internal_api.py:execute():145] {"error":"An internal error occurred. Please contact support."}
2023-04-19 13:28:28,565 WARNING MainThread:22554 [wandb_init.py:init():952] interrupted
Traceback (most recent call last):
  File "/home/sohui/miniconda3/envs/test/lib/python3.8/site-packages/wandb/sdk/wandb_init.py", line 931, in init
    run = wi.init()
  File "/home/sohui/miniconda3/envs/test/lib/python3.8/site-packages/wandb/sdk/wandb_init.py", line 579, in init
    ret = backend.interface.communicate_run(run, timeout=30)
  File "/home/sohui/miniconda3/envs/test/lib/python3.8/site-packages/wandb/sdk/interface/interface.py", line 210, in communicate_run
    return self._communicate_run(run, timeout=timeout)
  File "/home/sohui/miniconda3/envs/test/lib/python3.8/site-packages/wandb/sdk/interface/interface_shared.py", line 311, in _communicate_run
    resp = self._communicate(req, timeout=timeout)
  File "/home/sohui/miniconda3/envs/test/lib/python3.8/site-packages/wandb/sdk/interface/interface_shared.py", line 213, in _communicate
    return self._communicate_async(rec, local=local).get(timeout=timeout)
  File "/home/sohui/miniconda3/envs/test/lib/python3.8/site-packages/wandb/sdk/interface/router.py", line 37, in get
    is_set = self._object_ready.wait(timeout)
  File "/home/sohui/miniconda3/envs/test/lib/python3.8/threading.py", line 558, in wait
    signaled = self._cond.wait(timeout)
  File "/home/sohui/miniconda3/envs/test/lib/python3.8/threading.py", line 306, in wait
    gotit = waiter.acquire(True, timeout)
KeyboardInterrupt
