2023-04-19 13:28:22,288 INFO    MainThread:22710 [internal.py:wandb_internal():87] W&B internal server running at pid: 22710, started at: 2023-04-19 13:28:22.288061
2023-04-19 13:28:22,291 DEBUG   HandlerThread:22710 [handler.py:handle_request():130] handle_request: check_version
2023-04-19 13:28:22,292 INFO    WriterThread:22710 [datastore.py:open_for_write():77] open: /home/sohui/code/SSL_brats/code/wandb/run-20230419_132821-335vdtgb/run-335vdtgb.wandb
2023-04-19 13:28:22,295 DEBUG   SenderThread:22710 [sender.py:send():234] send: header
2023-04-19 13:28:22,296 DEBUG   SenderThread:22710 [sender.py:send_request():248] send_request: check_version
2023-04-19 13:28:22,372 DEBUG   SenderThread:22710 [sender.py:send():234] send: run
2023-04-19 13:28:22,604 ERROR   SenderThread:22710 [internal_api.py:execute():144] 500 response executing GraphQL.
2023-04-19 13:28:22,604 ERROR   SenderThread:22710 [internal_api.py:execute():145] {"error":"An internal error occurred. Please contact support."}
2023-04-19 13:28:23,987 ERROR   SenderThread:22710 [internal_api.py:execute():144] 500 response executing GraphQL.
2023-04-19 13:28:23,988 ERROR   SenderThread:22710 [internal_api.py:execute():145] {"error":"An internal error occurred. Please contact support."}
2023-04-19 13:28:26,646 ERROR   SenderThread:22710 [internal_api.py:execute():144] 500 response executing GraphQL.
2023-04-19 13:28:26,646 ERROR   SenderThread:22710 [internal_api.py:execute():145] {"error":"An internal error occurred. Please contact support."}
2023-04-19 13:28:26,646 ERROR   SenderThread:22710 [retry.py:__call__():126] Retry attempt failed:
Traceback (most recent call last):
  File "/home/sohui/miniconda3/envs/test/lib/python3.8/site-packages/wandb/sdk/lib/retry.py", line 102, in __call__
    result = self._call_fn(*args, **kwargs)
  File "/home/sohui/miniconda3/envs/test/lib/python3.8/site-packages/wandb/sdk/internal/internal_api.py", line 147, in execute
    six.reraise(*sys.exc_info())
  File "/home/sohui/miniconda3/envs/test/lib/python3.8/site-packages/six.py", line 719, in reraise
    raise value
  File "/home/sohui/miniconda3/envs/test/lib/python3.8/site-packages/wandb/sdk/internal/internal_api.py", line 141, in execute
    return self.client.execute(*args, **kwargs)
  File "/home/sohui/miniconda3/envs/test/lib/python3.8/site-packages/wandb/vendor/gql-0.2.0/gql/client.py", line 52, in execute
    result = self._get_result(document, *args, **kwargs)
  File "/home/sohui/miniconda3/envs/test/lib/python3.8/site-packages/wandb/vendor/gql-0.2.0/gql/client.py", line 60, in _get_result
    return self.transport.execute(document, *args, **kwargs)
  File "/home/sohui/miniconda3/envs/test/lib/python3.8/site-packages/wandb/vendor/gql-0.2.0/gql/transport/requests.py", line 39, in execute
    request.raise_for_status()
  File "/home/sohui/miniconda3/envs/test/lib/python3.8/site-packages/requests/models.py", line 953, in raise_for_status
    raise HTTPError(http_error_msg, response=self)
requests.exceptions.HTTPError: 500 Server Error: Internal Server Error for url: https://api.wandb.ai/graphql
2023-04-19 13:28:28,565 WARNING MainThread:22710 [internal.py:wandb_internal():146] Internal process interrupt: 1
2023-04-19 13:28:30,220 WARNING MainThread:22710 [internal.py:wandb_internal():146] Internal process interrupt: 2
2023-04-19 13:28:30,220 ERROR   MainThread:22710 [internal.py:wandb_internal():149] Internal process interrupted.
2023-04-19 13:28:30,373 INFO    WriterThread:22710 [datastore.py:close():281] close: /home/sohui/code/SSL_brats/code/wandb/run-20230419_132821-335vdtgb/run-335vdtgb.wandb
2023-04-19 13:28:30,381 INFO    HandlerThread:22710 [handler.py:finish():731] shutting down handler
2023-04-19 13:28:31,884 ERROR   SenderThread:22710 [internal_api.py:execute():144] 500 response executing GraphQL.
2023-04-19 13:28:31,885 ERROR   SenderThread:22710 [internal_api.py:execute():145] {"error":"An internal error occurred. Please contact support."}
2023-04-19 13:29:07,773 ERROR   SenderThread:22710 [internal_api.py:execute():144] 500 response executing GraphQL.
2023-04-19 13:29:07,774 ERROR   SenderThread:22710 [internal_api.py:execute():145] {"error":"driver: bad connection"}
2023-04-19 13:29:47,340 INFO    SenderThread:22710 [dir_watcher.py:__init__():169] watching files in: /home/sohui/code/SSL_brats/code/wandb/run-20230419_132821-335vdtgb/files
2023-04-19 13:29:47,340 INFO    SenderThread:22710 [sender.py:_start_run_threads():804] run started: 335vdtgb with start time 1681878501
2023-04-19 13:29:47,340 INFO    SenderThread:22710 [sender.py:finish():1070] shutting down sender
2023-04-19 13:29:47,340 INFO    SenderThread:22710 [dir_watcher.py:finish():283] shutting down directory watcher
2023-04-19 13:29:48,340 INFO    SenderThread:22710 [dir_watcher.py:finish():313] scan: /home/sohui/code/SSL_brats/code/wandb/run-20230419_132821-335vdtgb/files
2023-04-19 13:29:48,341 INFO    SenderThread:22710 [dir_watcher.py:finish():327] scan save: /home/sohui/code/SSL_brats/code/wandb/run-20230419_132821-335vdtgb/files/config.yaml config.yaml
2023-04-19 13:29:48,341 INFO    SenderThread:22710 [file_pusher.py:finish():177] shutting down file pusher
2023-04-19 13:29:48,341 INFO    SenderThread:22710 [file_pusher.py:join():182] waiting for file pusher
2023-04-19 13:29:49,117 INFO    Thread-10 :22710 [upload_job.py:push():137] Uploaded file /home/sohui/code/SSL_brats/code/wandb/run-20230419_132821-335vdtgb/files/config.yaml
2023-04-19 13:29:49,596 INFO    MainThread:22710 [internal.py:handle_exit():77] Internal process exited
